Workbook

Sheet V+MC Currency
A1: Block | B1: Currency | C1: Label C | D1: Label D | E1: Label E | F1: Label F | G1: Label G | H1: Label H | I1: VLOOKUP | N1: Jan24 | O1: Feb24 | P1: Mar24 | Q1: Apr24 | R1: May24 | S1: Jun24 | T1: Jul24 | U1: Aug24 | V1: Sep24 | W1: Oct24 | X1: Nov24 | Y1: Dec24 | Z1: Jan25 | AA1: Feb25 | AB1: Mar25 | AC1: Apr25 | AD1: May25 | AE1: Jun25 | AF1: Jul25 | AG1: Aug25 | AH1: Sep25 | AJ1: Q1 2024 | AK1: Q2 2024 | AL1: Q3 2024 | AM1: Q4 2024 | AN1: Q1 2025 | AO1: Q2 2025 | AP1: Q3 2025 | AQ1: Q4 2025 | AR1: Q1 2026
A47: MC Credit Cards | B47: HKD | C47: HKD_C | D47: HKD_D | E47: HKD_E | F47: HKD_F | G47: HKD_G | H47: HKD_H | I47: =VLOOKUP(B47,Data!A:B,2,FALSE) | N47: 0 | O47: 0 | P47: 0 | Q47: 0 | R47: 0 | S47: 0 | T47: 0 | U47: 0 | V47: 0 | W47: 0 | X47: 0 | Y47: 0 | Z47: 0 | AA47: 0 | AB47: 0 | AC47: 0 | AD47: 0 | AE47: 0 | AF47: 0 | AG47: 0 | AH47: 0
B48: JPY | C48: JPY_C | D48: JPY_D | E48: JPY_E | F48: JPY_F | G48: JPY_G | H48: JPY_H | I48: =VLOOKUP(B48,Data!A:B,2,FALSE) | N48: 0 | O48: 0 | P48: 0 | Q48: 0 | R48: 0 | S48: 0 | T48: 0 | U48: 0 | V48: 0 | W48: 0 | X48: 0 | Y48: 0 | Z48: 0 | AA48: 0 | AB48: 0 | AC48: 0 | AD48: 0 | AE48: 0 | AF48: 0 | AG48: 0 | AH48: 0
B49: TWD | C49: TWD_C | D49: TWD_D | E49: TWD_E | F49: TWD_F | G49: TWD_G | H49: TWD_H | I49: =VLOOKUP(B49,Data!A:B,2,FALSE) | N49: 0 | O49: 0 | P49: 0 | Q49: 0 | R49: 0 | S49: 0 | T49: 0 | U49: 0 | V49: 0 | W49: 0 | X49: 0 | Y49: 0 | Z49: 0 | AA49: 0 | AB49: 0 | AC49: 0 | AD49: 0 | AE49: 0 | AF49: 0 | AG49: 0 | AH49: 0
B50: KRW | C50: KRW_C | D50: KRW_D | E50: KRW_E | F50: KRW_F | G50: KRW_G | H50: KRW_H | I50: =VLOOKUP(B50,Data!A:B,2,FALSE) | N50: 0 | O50: 0 | P50: 0 | Q50: 0 | R50: 0 | S50: 0 | T50: 0 | U50: 0 | V50: 0 | W50: 0 | X50: 0 | Y50: 0 | Z50: 0 | AA50: 0 | AB50: 0 | AC50: 0 | AD50: 0 | AE50: 0 | AF50: 0 | AG50: 0 | AH50: 0
B51: RMB | C51: RMB_C | D51: RMB_D | E51: RMB_E | F51: RMB_F | G51: RMB_G | H51: RMB_H | I51: =VLOOKUP(B51,Data!A:B,2,FALSE) | N51: 0 | O51: 0 | P51: 0 | Q51: 0 | R51: 0 | S51: 0 | T51: 0 | U51: 0 | V51: 0 | W51: 0 | X51: 0 | Y51: 0 | Z51: 0 | AA51: 0 | AB51: 0 | AC51: 0 | AD51: 0 | AE51: 0 | AF51: 0 | AG51: 0 | AH51: 0
B52: PHP | C52: PHP_C | D52: PHP_D | E52: PHP_E | F52: PHP_F | G52: PHP_G | H52: PHP_H | I52: =VLOOKUP(B52,Data!A:B,2,FALSE) | N52: 0 | O52: 0 | P52: 0 | Q52: 0 | R52: 0 | S52: 0 | T52: 0 | U52: 0 | V52: 0 | W52: 0 | X52: 0 | Y52: 0 | Z52: 0 | AA52: 0 | AB52: 0 | AC52: 0 | AD52: 0 | AE52: 0 | AF52: 0 | AG52: 0 | AH52: 0
B53: IDR | C53: IDR_C | D53: IDR_D | E53: IDR_E | F53: IDR_F | G53: IDR_G | H53: IDR_H | I53: =VLOOKUP(B53,Data!A:B,2,FALSE) | N53: 0 | O53: 0 | P53: 0 | Q53: 0 | R53: 0 | S53: 0 | T53: 0 | U53: 0 | V53: 0 | W53: 0 | X53: 0 | Y53: 0 | Z53: 0 | AA53: 0 | AB53: 0 | AC53: 0 | AD53: 0 | AE53: 0 | AF53: 0 | AG53: 0 | AH53: 0
B54: THB | C54: THB_C | D54: THB_D | E54: THB_E | F54: THB_F | G54: THB_G | H54: THB_H | I54: =VLOOKUP(B54,Data!A:B,2,FALSE) | N54: 0 | O54: 0 | P54: 0 | Q54: 0 | R54: 0 | S54: 0 | T54: 0 | U54: 0 | V54: 0 | W54: 0 | X54: 0 | Y54: 0 | Z54: 0 | AA54: 0 | AB54: 0 | AC54: 0 | AD54: 0 | AE54: 0 | AF54: 0 | AG54: 0 | AH54: 0
B55: VND | C55: VND_C | D55: VND_D | E55: VND_E | F55: VND_F | G55: VND_G | H55: VND_H | I55: =VLOOKUP(B55,Data!A:B,2,FALSE) | N55: 0 | O55: 0 | P55: 0 | Q55: 0 | R55: 0 | S55: 0 | T55: 0 | U55: 0 | V55: 0 | W55: 0 | X55: 0 | Y55: 0 | Z55: 0 | AA55: 0 | AB55: 0 | AC55: 0 | AD55: 0 | AE55: 0 | AF55: 0 | AG55: 0 | AH55: 0
B56: MYR | C56: MYR_C | D56: MYR_D | E56: MYR_E | F56: MYR_F | G56: MYR_G | H56: MYR_H | I56: =VLOOKUP(B56,Data!A:B,2,FALSE) | N56: 0 | O56: 0 | P56: 0 | Q56: 0 | R56: 0 | S56: 0 | T56: 0 | U56: 0 | V56: 0 | W56: 0 | X56: 0 | Y56: 0 | Z56: 0 | AA56: 0 | AB56: 0 | AC56: 0 | AD56: 0 | AE56: 0 | AF56: 0 | AG56: 0 | AH56: 0
B57: INR | C57: INR_C | D57: INR_D | E57: INR_E | F57: INR_F | G57: INR_G | H57: INR_H | I57: =VLOOKUP(B57,Data!A:B,2,FALSE) | N57: 0 | O57: 0 | P57: 0 | Q57: 0 | R57: 0 | S57: 0 | T57: 0 | U57: 0 | V57: 0 | W57: 0 | X57: 0 | Y57: 0 | Z57: 0 | AA57: 0 | AB57: 0 | AC57: 0 | AD57: 0 | AE57: 0 | AF57: 0 | AG57: 0 | AH57: 0
B58: EUR | C58: EUR_C | D58: EUR_D | E58: EUR_E | F58: EUR_F | G58: EUR_G | H58: EUR_H | I58: =VLOOKUP(B58,Data!A:B,2,FALSE) | N58: 0 | O58: 0 | P58: 0 | Q58: 0 | R58: 0 | S58: 0 | T58: 0 | U58: 0 | V58: 0 | W58: 0 | X58: 0 | Y58: 0 | Z58: 0 | AA58: 0 | AB58: 0 | AC58: 0 | AD58: 0 | AE58: 0 | AF58: 0 | AG58: 0 | AH58: 0
B59: USD | C59: USD_C | D59: USD_D | E59: USD_E | F59: USD_F | G59: USD_G | H59: USD_H | I59: =VLOOKUP(B59,Data!A:B,2,FALSE) | N59: 0 | O59: 0 | P59: 0 | Q59: 0 | R59: 0 | S59: 0 | T59: 0 | U59: 0 | V59: 0 | W59: 0 | X59: 0 | Y59: 0 | Z59: 0 | AA59: 0 | AB59: 0 | AC59: 0 | AD59: 0 | AE59: 0 | AF59: 0 | AG59: 0 | AH59: 0
... B62: OTH | C62: OTH_C | D62: OTH_D | E62: OTH_E | F62: OTH_F | G62: OTH_G | H62: OTH_H | I62: =VLOOKUP(B62,Data!A:B,2,FALSE) | N62: 0 | O62: 0 | P62: 0 | Q62: 0 | R62: 0 | S62: 0 | T62: 0 | U62: 0 | V62: 0 | W62: 0 | X62: 0 | Y62: 0 | Z62: 0 | AA62: 0 | AB62: 0 | AC62: 0 | AD62: 0 | AE62: 0 | AF62: 0 | AG62: 0 | AH62: 0
A66: Total MC Credit Cards | B66: TOTAL | N66: =SUM(N47:N65) | O66: =SUM(O47:O65) | P66: =SUM(P47:P65) | Q66: =SUM(Q47:Q65) | R66: =SUM(R47:R65) | S66: =SUM(S47:S65) | T66: =SUM(T47:T65) | U66: =SUM(U47:U65) | ... AH66: =SUM(AH47:AH65) | AJ66: =SUM(N66,O66,P66) | AK66: =SUM(Q66,R66,S66) | AL66: =SUM(T66,U66,V66) | AM66: =SUM(W66,X66,Y66) | AN66: =SUM(Z66,AA66,AB66) | AO66: =SUM(AC66,AD66,AE66) | AP66: =SUM(AF66,AG66,AH66) | AQ66: =SUM(AI66,AJ66,AK66) | AR66: =SUM(AL66,AM66,AN66)
A67: MC Debit Cards | B67: HKD | C67: HKD_C | D67: HKD_D | E67: HKD_E | F67: HKD_F | G67: HKD_G | H67: HKD_H | I67: =VLOOKUP(B67,Data!A:B,2,FALSE) | N67: 0 | O67: 0 | P67: 0 | Q67: 0 | R67: 0 | S67: 0 | T67: 0 | U67: 0 | V67: 0 | W67: 0 | X67: 0 | Y67: 0 | Z67: 0 | AA67: 0 | AB67: 0 | AC67: 0 | AD67: 0 | AE67: 0 | AF67: 0 | AG67: 0 | AH67: 0
B68: JPY | C68: JPY_C | D68: JPY_D | E68: JPY_E | F68: JPY_F | G68: JPY_G | H68: JPY_H | I68: =VLOOKUP(B68,Data!A:B,2,FALSE) | N68: 0 | O68: 0 | P68: 0 | Q68: 0 | R68: 0 | S68: 0 | T68: 0 | U68: 0 | V68: 0 | W68: 0 | X68: 0 | Y68: 0 | Z68: 0 | AA68: 0 | AB68: 0 | AC68: 0 | AD68: 0 | AE68: 0 | AF68: 0 | AG68: 0 | AH68: 0
B69: TWD | C69: TWD_C | D69: TWD_D | E69: TWD_E | F69: TWD_F | G69: TWD_G | H69: TWD_H | I69: =VLOOKUP(B69,Data!A:B,2,FALSE) | N69: 0 | O69: 0 | P69: 0 | Q69: 0 | R69: 0 | S69: 0 | T69: 0 | U69: 0 | V69: 0 | W69: 0 | X69: 0 | Y69: 0 | Z69: 0 | AA69: 0 | AB69: 0 | AC69: 0 | AD69: 0 | AE69: 0 | AF69: 0 | AG69: 0 | AH69: 0
B70: KRW | C70: KRW_C | D70: KRW_D | E70: KRW_E | F70: KRW_F | G70: KRW_G | H70: KRW_H | I70: =VLOOKUP(B70,Data!A:B,2,FALSE) | N70: 0 | O70: 0 | P70: 0 | Q70: 0 | R70: 0 | S70: 0 | T70: 0 | U70: 0 | V70: 0 | W70: 0 | X70: 0 | Y70: 0 | Z70: 0 | AA70: 0 | AB70: 0 | AC70: 0 | AD70: 0 | AE70: 0 | AF70: 0 | AG70: 0 | AH70: 0
B71: RMB | C71: RMB_C | D71: RMB_D | E71: RMB_E | F71: RMB_F | G71: RMB_G | H71: RMB_H | I71: =VLOOKUP(B71,Data!A:B,2,FALSE) | N71: 0 | O71: 0 | P71: 0 | Q71: 0 | R71: 0 | S71: 0 | T71: 0 | U71: 0 | V71: 0 | W71: 0 | X71: 0 | Y71: 0 | Z71: 0 | AA71: 0 | AB71: 0 | AC71: 0 | AD71: 0 | AE71: 0 | AF71: 0 | AG71: 0 | AH71: 0
B72: PHP | C72: PHP_C | D72: PHP_D | E72: PHP_E | F72: PHP_F | G72: PHP_G | H72: PHP_H | I72: =VLOOKUP(B72,Data!A:B,2,FALSE) | N72: 0 | O72: 0 | P72: 0 | Q72: 0 | R72: 0 | S72: 0 | T72: 0 | U72: 0 | V72: 0 | W72: 0 | X72: 0 | Y72: 0 | Z72: 0 | AA72: 0 | AB72: 0 | AC72: 0 | AD72: 0 | AE72: 0 | AF72: 0 | AG72: 0 | AH72: 0
B73: IDR | C73: IDR_C | D73: IDR_D | E73: IDR_E | F73: IDR_F | G73: IDR_G | H73: IDR_H | I73: =VLOOKUP(B73,Data!A:B,2,FALSE) | N73: 0 | O73: 0 | P73: 0 | Q73: 0 | R73: 0 | S73: 0 | T73: 0 | U73: 0 | V73: 0 | W73: 0 | X73: 0 | Y73: 0 | Z73: 0 | AA73: 0 | AB73: 0 | AC73: 0 | AD73: 0 | AE73: 0 | AF73: 0 | AG73: 0 | AH73: 0
B74: THB | C74: THB_C | D74: THB_D | E74: THB_E | F74: THB_F | G74: THB_G | H74: THB_H | I74: =VLOOKUP(B74,Data!A:B,2,FALSE) | N74: 0 | O74: 0 | P74: 0 | Q74: 0 | R74: 0 | S74: 0 | T74: 0 | U74: 0 | V74: 0 | W74: 0 | X74: 0 | Y74: 0 | Z74: 0 | AA74: 0 | AB74: 0 | AC74: 0 | AD74: 0 | AE74: 0 | AF74: 0 | AG74: 0 | AH74: 0
B75: VND | C75: VND_C | D75: VND_D | E75: VND_E | F75: VND_F | G75: VND_G | H75: VND_H | I75: =VLOOKUP(B75,Data!A:B,2,FALSE) | N75: 0 | O75: 0 | P75: 0 | Q75: 0 | R75: 0 | S75: 0 | T75: 0 | U75: 0 | V75: 0 | W75: 0 | X75: 0 | Y75: 0 | Z75: 0 | AA75: 0 | AB75: 0 | AC75: 0 | AD75: 0 | AE75: 0 | AF75: 0 | AG75: 0 | AH75: 0
B76: MYR | C76: MYR_C | D76: MYR_D | E76: MYR_E | F76: MYR_F | G76: MYR_G | H76: MYR_H | I76: =VLOOKUP(B76,Data!A:B,2,FALSE) | N76: 0 | O76: 0 | P76: 0 | Q76: 0 | R76: 0 | S76: 0 | T76: 0 | U76: 0 | V76: 0 | W76: 0 | X76: 0 | Y76: 0 | Z76: 0 | AA76: 0 | AB76: 0 | AC76: 0 | AD76: 0 | AE76: 0 | AF76: 0 | AG76: 0 | AH76: 0
B77: INR | C77: INR_C | D77: INR_D | E77: INR_E | F77: INR_F | G77: INR_G | H77: INR_H | I77: =VLOOKUP(B77,Data!A:B,2,FALSE) | N77: 0 | O77: 0 | P77: 0 | Q77: 0 | R77: 0 | S77: 0 | T77: 0 | U77: 0 | V77: 0 | W77: 0 | X77: 0 | Y77: 0 | Z77: 0 | AA77: 0 | AB77: 0 | AC77: 0 | AD77: 0 | AE77: 0 | AF77: 0 | AG77: 0 | AH77: 0
B78: EUR | C78: EUR_C | D78: EUR_D | E78: EUR_E | F78: EUR_F | G78: EUR_G | H78: EUR_H | I78: =VLOOKUP(B78,Data!A:B,2,FALSE) | N78: 0 | O78: 0 | P78: 0 | Q78: 0 | R78: 0 | S78: 0 | T78: 0 | U78: 0 | V78: 0 | W78: 0 | X78: 0 | Y78: 0 | Z78: 0 | AA78: 0 | AB78: 0 | AC78: 0 | AD78: 0 | AE78: 0 | AF78: 0 | AG78: 0 | AH78: 0
B79: USD | C79: USD_C | D79: USD_D | E79: USD_E | F79: USD_F | G79: USD_G | H79: USD_H | I79: =VLOOKUP(B79,Data!A:B,2,FALSE) | N79: 0 | O79: 0 | P79: 0 | Q79: 0 | R79: 0 | S79: 0 | T79: 0 | U79: 0 | V79: 0 | W79: 0 | X79: 0 | Y79: 0 | Z79: 0 | AA79: 0 | AB79: 0 | AC79: 0 | AD79: 0 | AE79: 0 | AF79: 0 | AG79: 0 | AH79: 0
... B82: OTH | C82: OTH_C | D82: OTH_D | E82: OTH_E | F82: OTH_F | G82: OTH_G | H82: OTH_H | I82: =VLOOKUP(B82,Data!A:B,2,FALSE) | N82: 0 | O82: 0 | P82: 0 | Q82: 0 | R82: 0 | S82: 0 | T82: 0 | U82: 0 | V82: 0 | W82: 0 | X82: 0 | Y82: 0 | Z82: 0 | AA82: 0 | AB82: 0 | AC82: 0 | AD82: 0 | AE82: 0 | AF82: 0 | AG82: 0 | AH82: 0
A86: Total MC Debit Cards | B86: TOTAL | N86: =SUM(N67:N85) | O86: =SUM(O67:O85) | P86: =SUM(P67:P85) | Q86: =SUM(Q67:Q85) | R86: =SUM(R67:R85) | S86: =SUM(S67:S85) | T86: =SUM(T67:T85) | U86: =SUM(U67:U85) | ... AH86: =SUM(AH67:AH85) | AJ86: =SUM(N86,O86,P86) | AK86: =SUM(Q86,R86,S86) | AL86: =SUM(T86,U86,V86) | AM86: =SUM(W86,X86,Y86) | AN86: =SUM(Z86,AA86,AB86) | AO86: =SUM(AC86,AD86,AE86) | AP86: =SUM(AF86,AG86,AH86) | AQ86: =SUM(AI86,AJ86,AK86) | AR86: =SUM(AL86,AM86,AN86)
A87: Visa Credit Cards | B87: HKD | C87: HKD_C | D87: HKD_D | E87: HKD_E | F87: HKD_F | G87: HKD_G | H87: HKD_H | I87: =VLOOKUP(B87,Data!A:B,2,FALSE) | N87: 0 | O87: 0 | P87: 0 | Q87: 0 | R87: 0 | S87: 0 | T87: 0 | U87: 0 | V87: 0 | W87: 0 | X87: 0 | Y87: 0 | Z87: 0 | AA87: 0 | AB87: 0 | AC87: 0 | AD87: 0 | AE87: 0 | AF87: 0 | AG87: 0 | AH87: 0
B88: JPY | C88: JPY_C | D88: JPY_D | E88: JPY_E | F88: JPY_F | G88: JPY_G | H88: JPY_H | I88: =VLOOKUP(B88,Data!A:B,2,FALSE) | N88: 0 | O88: 0 | P88: 0 | Q88: 0 | R88: 0 | S88: 0 | T88: 0 | U88: 0 | V88: 0 | W88: 0 | X88: 0 | Y88: 0 | Z88: 0 | AA88: 0 | AB88: 0 | AC88: 0 | AD88: 0 | AE88: 0 | AF88: 0 | AG88: 0 | AH88: 0
B89: TWD | C89: TWD_C | D89: TWD_D | E89: TWD_E | F89: TWD_F | G89: TWD_G | H89: TWD_H | I89: =VLOOKUP(B89,Data!A:B,2,FALSE) | N89: 0 | O89: 0 | P89: 0 | Q89: 0 | R89: 0 | S89: 0 | T89: 0 | U89: 0 | V89: 0 | W89: 0 | X89: 0 | Y89: 0 | Z89: 0 | AA89: 0 | AB89: 0 | AC89: 0 | AD89: 0 | AE89: 0 | AF89: 0 | AG89: 0 | AH89: 0
B90: KRW | C90: KRW_C | D90: KRW_D | E90: KRW_E | F90: KRW_F | G90: KRW_G | H90: KRW_H | I90: =VLOOKUP(B90,Data!A:B,2,FALSE) | N90: 0 | O90: 0 | P90: 0 | Q90: 0 | R90: 0 | S90: 0 | T90: 0 | U90: 0 | V90: 0 | W90: 0 | X90: 0 | Y90: 0 | Z90: 0 | AA90: 0 | AB90: 0 | AC90: 0 | AD90: 0 | AE90: 0 | AF90: 0 | AG90: 0 | AH90: 0
B91: RMB | C91: RMB_C | D91: RMB_D | E91: RMB_E | F91: RMB_F | G91: RMB_G | H91: RMB_H | I91: =VLOOKUP(B91,Data!A:B,2,FALSE) | N91: 0 | O91: 0 | P91: 0 | Q91: 0 | R91: 0 | S91: 0 | T91: 0 | U91: 0 | V91: 0 | W91: 0 | X91: 0 | Y91: 0 | Z91: 0 | AA91: 0 | AB91: 0 | AC91: 0 | AD91: 0 | AE91: 0 | AF91: 0 | AG91: 0 | AH91: 0
B92: PHP | C92: PHP_C | D92: PHP_D | E92: PHP_E | F92: PHP_F | G92: PHP_G | H92: PHP_H | I92: =VLOOKUP(B92,Data!A:B,2,FALSE) | N92: 0 | O92: 0 | P92: 0 | Q92: 0 | R92: 0 | S92: 0 | T92: 0 | U92: 0 | V92: 0 | W92: 0 | X92: 0 | Y92: 0 | Z92: 0 | AA92: 0 | AB92: 0 | AC92: 0 | AD92: 0 | AE92: 0 | AF92: 0 | AG92: 0 | AH92: 0
B93: IDR | C93: IDR_C | D93: IDR_D | E93: IDR_E | F93: IDR_F | G93: IDR_G | H93: IDR_H | I93: =VLOOKUP(B93,Data!A:B,2,FALSE) | N93: 0 | O93: 0 | P93: 0 | Q93: 0 | R93: 0 | S93: 0 | T93: 0 | U93: 0 | V93: 0 | W93: 0 | X93: 0 | Y93: 0 | Z93: 0 | AA93: 0 | AB93: 0 | AC93: 0 | AD93: 0 | AE93: 0 | AF93: 0 | AG93: 0 | AH93: 0
B94: THB | C94: THB_C | D94: THB_D | E94: THB_E | F94: THB_F | G94: THB_G | H94: THB_H | I94: =VLOOKUP(B94,Data!A:B,2,FALSE) | N94: 0 | O94: 0 | P94: 0 | Q94: 0 | R94: 0 | S94: 0 | T94: 0 | U94: 0 | V94: 0 | W94: 0 | X94: 0 | Y94: 0 | Z94: 0 | AA94: 0 | AB94: 0 | AC94: 0 | AD94: 0 | AE94: 0 | AF94: 0 | AG94: 0 | AH94: 0
B95: VND | C95: VND_C | D95: VND_D | E95: VND_E | F95: VND_F | G95: VND_G | H95: VND_H | I95: =VLOOKUP(B95,Data!A:B,2,FALSE) | N95: 0 | O95: 0 | P95: 0 | Q95: 0 | R95: 0 | S95: 0 | T95: 0 | U95: 0 | V95: 0 | W95: 0 | X95: 0 | Y95: 0 | Z95: 0 | AA95: 0 | AB95: 0 | AC95: 0 | AD95: 0 | AE95: 0 | AF95: 0 | AG95: 0 | AH95: 0
...

Sheet Currency Dashboard
A1: Currency Market Share Dashboard
A3: Online Share by Currency | E3: POS Share by Currency
A4: Currency | B4: Share % | E4: Currency | F4: Share %
A5: AUD | B5: 0 | E5: AUD | F5: 0
A6: CAD | B6: 0 | E6: CAD | F6: 0
A7: EUR | B7: 0 | E7: EUR | F7: 0
A8: GBP | B8: 0 | E8: GBP | F8: 0
A9: HKD | B9: 0 | E9: HKD | F9: 0
A10: IDR | B10: 0 | E10: IDR | F10: 0
A11: INR | B11: 0 | E11: INR | F11: 0
A12: JPY | B12: 0 | E12: JPY | F12: 0
A13: MYR | B13: 0 | E13: MYR | F13: 0
A14: NZD | B14: 0 | E14: NZD | F14: 0
A15: THB | B15: 0 | E15: THB | F15: 0
A16: USD | B16: 0 | E16: USD | F16: 0
A17: OTH | B17: 0 | E17: OTH | F17: 0
A39: Currency Cross-Tabulation Matrix
B40: AUD | C40: CAD | D40: EUR | E40: GBP | F40: HKD | G40: IDR | H40: INR | I40: JPY | J40: MYR | K40: NZD | L40: THB | M40: USD | N40: OTH
A41: AUD | B41: 0 | C41: 0 | D41: 0 | E41: 0 | F41: 0 | G41: 0 | H41: 0 | I41: 0 | J41: 0 | K41: 0 | L41: 0 | M41: 0 | N41: 0
A42: CAD | B42: 0 | C42: 0 | D42: 0 | E42: 0 | F42: 0 | G42: 0 | H42: 0 | I42: 0 | J42: 0 | K42: 0 | L42: 0 | M42: 0 | N42: 0
A43: EUR | B43: 0 | C43: 0 | D43: 0 | E43: 0 | F43: 0 | G43: 0 | H43: 0 | I43: 0 | J43: 0 | K43: 0 | L43: 0 | M43: 0 | N43: 0
A44: GBP | B44: 0 | C44: 0 | D44: 0 | E44: 0 | F44: 0 | G44: 0 | H44: 0 | I44: 0 | J44: 0 | K44: 0 | L44: 0 | M44: 0 | N44: 0
A45: HKD | B45: 0 | C45: 0 | D45: 0 | E45: 0 | F45: 0 | G45: 0 | H45: 0 | I45: 0 | J45: 0 | K45: 0 | L45: 0 | M45: 0 | N45: 0
A46: IDR | B46: 0 | C46: 0 | D46: 0 | E46: 0 | F46: 0 | G46: 0 | H46: 0 | I46: 0 | J46: 0 | K46: 0 | L46: 0 | M46: 0 | N46: 0
A47: INR | B47: 0 | C47: 0 | D47: 0 | E47: 0 | F47: 0 | G47: 0 | H47: 0 | I47: 0 | J47: 0 | K47: 0 | L47: 0 | M47: 0 | N47: 0
A48: JPY | B48: 0 | C48: 0 | D48: 0 | E48: 0 | F48: 0 | G48: 0 | H48: 0 | I48: 0 | J48: 0 | K48: 0 | L48: 0 | M48: 0 | N48: 0
A49: MYR | B49: 0 | C49: 0 | D49: 0 | E49: 0 | F49: 0 | G49: 0 | H49: 0 | I49: 0 | J49: 0 | K49: 0 | L49: 0 | M49: 0 | N49: 0
A50: NZD | B50: 0 | C50: 0 | D50: 0 | E50: 0 | F50: 0 | G50: 0 | H50: 0 | I50: 0 | J50: 0 | K50: 0 | L50: 0 | M50: 0 | N50: 0
A51: THB | B51: 0 | C51: 0 | D51: 0 | E51: 0 | F51: 0 | G51: 0 | H51: 0 | I51: 0 | J51: 0 | K51: 0 | L51: 0 | M51: 0 | N51: 0
A52: USD | B52: 0 | C52: 0 | D52: 0 | E52: 0 | F52: 0 | G52: 0 | H52: 0 | I52: 0 | J52: 0 | K52: 0 | L52: 0 | M52: 0 | N52: 0
A53: OTH | B53: 0 | C53: 0 | D53: 0 | E53: 0 | F53: 0 | G53: 0 | H53: 0 | I53: 0 | J53: 0 | K53: 0 | L53: 0 | M53: 0 | N53: 0
